Workbook

Sheet Sheet2
A1: Consolidated Statement of Income - USD ($) | B1: 12 Months Ended
A2: $ in Millions | B2: Dec. 31, 2023 | C2: Dec. 31, 2024 | D2: Dec. 31, 2025
A3: REVENUES
A4: Revenues from franchised restaurants | B4: 15437 | C4: 15715 | D4: 16548
A5: Sales by Company-owned and operated restaurants | B5: 9742 | C5: 9782 | D5: 9690
A6: Other revenues | B6: 316 | C6: 423 | D6: 647
A7: Total revenues | B7: 25494 | C7: 25920 | D7: 26885
A8: OPERATING COSTS AND EXPENSES
A9: Franchised restaurants-occupancy expenses | B9: 2475 | C9: 2536 | D9: 2618
A10: Food & paper | B10: 3039 | C10: 2995 | D10: 3006
A11: Payroll & employee benefits | B11: 2886 | C11: 2959 | D11: 2905
A12: Occupancy & other operating expenses | B12: 2299 | C12: 2381 | D12: 2358
A13: Other restaurant expenses | B13: 232 | C13: 339 | D13: 564
A14: Depreciation and amortization | B14: 382 | C14: 447 | D14: 457
A15: Other | B15: 2435 | C15: 2412 | D15: 2583
A16: Other operating (income) expense, net | B16: 99 | C16: 139 | D16: 2
A17: Total operating costs and expenses | B17: 13847 | C17: 14208 | D17: 14492
A18: Operating income | B18: 11647 | C18: 11712 | D18: 12393
A19: Interest expense-net of capitalized interest of $29, $22 and $14 | B19: 1361 | C19: 1506 | D19: 1582
A20: Nonoperating (income) expense, net | B20: -236 | C20: -139 | D20: -87
... A28: Weighted-average shares outstanding–diluted | B28: 732.3 | C28: 721.9 | D28: 716.4
A30: Consolidated Statement of Cash Flows - USD ($) | D30: 12 Months Ended
A31: $ in Millions | B31: Dec. 31, 2023 | C31: Dec. 31, 2024 | D31: Dec. 31, 2025
A32: Operating activities
A33: Net income | B33: 8469 | C33: 8223 | D33: 8563
A34: Charges and credits:
A35: Depreciation and amortization | B35: 1978 | C35: 2097 | D35: 2199
A36: Deferred income taxes | B36: -686 | C36: -574 | D36: -126
A37: Share-based compensation expense | B37: 175 | C37: 172 | D37: 165
A38: Net (gain) loss on sale of restaurant and other businesses | B38: -103 | C38: -37 | D38: -149
A39: Other | B39: -113 | C39: 3 | D39: -207
A40: Changes in working capital items:
A41: Accounts receivable | B41: -161 | C41: 10 | D41: 231
A42: Inventories, prepaid expenses and other current assets | B42: 17 | C42: 71 | D42: -140
A43: Accounts payable | B43: 50 | C43: -10 | D43: 100
A44: Income taxes | B44: -220 | C44: -292 | D44: -239
A45: Other accrued liabilities | B45: 206 | C45: -217 | D45: 154
A46: Cash provided by operations | B46: 9612 | C46: 9447 | D46: 10551
A47: Investing activities
A48: Capital expenditures | B48: -2357 | C48: -2775 | D48: -3365
...

Sheet Income Statement
B3: McDonalds Corp
B4: MCD
B5: 3 Statement Financial Model
B7: Statement of Profit or Loss | D7: Actuals | G7: Projections
B8: Amounts in millions | C8: Units | D8: 45291 | E8: =EOMONTH(D8,12) -> 45657 | F8: =EOMONTH(E8,12) -> 46022 | G8: =EOMONTH(F8,12) -> 46387 | H8: =EOMONTH(G8,12) -> 46752 | I8: =EOMONTH(H8,12) -> 47118 | J8: =EOMONTH(I8,12) -> 47483 | K8: =EOMONTH(J8,12) -> 47848
C9: $ | D9: $ | E9: $ | F9: $ | G9: $ | H9: $ | I9: $ | J9: $ | K9: $
B10: Revenue | D10: =Sheet2!B7 -> 25494 | E10: =Sheet2!C7 -> 25920 | F10: =Sheet2!D7 -> 26885 | G10: =F10*(1+G27) -> 27557.125 | H10: =G10*(1+H27) -> 28246.053 | I10: =H10*(1+I27) -> 28952.204 | J10: =I10*(1+J27) -> 29676.01 | K10: =J10*(1+K27) -> 30417.91
B11: Cost of Sales | D11: =-SUM(Sheet2!B9:B13) -> -10931 | E11: =-SUM(Sheet2!C9:C13) -> -11210 | F11: =-SUM(Sheet2!D9:D13) -> -11451 | G11: =G28*G10 -> -11823.636 | H11: =H28*H10 -> -12121.972 | I11: =I28*I10 -> -12392.901 | J11: =J28*J10 -> -12723.711 | K11: =K28*K10 -> -13038.711
B12: Gross Profit | D12: =SUM(D10:D11) -> 14563 | E12: =SUM(E10:E11) -> 14710 | F12: =SUM(F10:F11) -> 15434 | G12: =SUM(G10:G11) -> 15733.489 | H12: =SUM(H10:H11) -> 16124.081 | I12: =SUM(I10:I11) -> 16559.303 | J12: =SUM(J10:J11) -> 16952.299 | K12: =SUM(K10:K11) -> 17379.199
B13: Operating Expenses | D13: =-SUM(Sheet2!B15:B16) -> -2534 | E13: =-SUM(Sheet2!C15:C16) -> -2551 | F13: =-SUM(Sheet2!D15:D16) -> -2585 | G13: =G29*G10 -> -2700.2714 | H13: =H29*H10 -> -2754.5233 | I13: =I29*I10 -> -2814.7071 | J13: =J29*J10 -> -2895.6476 | K13: =K29*K10 -> -2963.8535
B14: Other expenses | D14: =-Sheet2!B14 -> -382 | E14: =-Sheet2!C14 -> -447 | F14: =-Sheet2!D14 -> -457 | G14: =G31*G10 -> -452.19051 | H14: =H31*H10 -> -476.91485 | I14: =I31*I10 -> -485.35313 | J14: =J31*J10 -> -495.16845 | K14: =K31*K10 -> -510.35231
B15: Operating Income | D15: =SUM(D12:D14) -> 11647 | E15: =SUM(E12:E14) -> 11712 | F15: =SUM(F12:F14) -> 12392 | G15: =SUM(G12:G14) -> 12581.027 | H15: =SUM(H12:H14) -> 12892.643 | I15: =SUM(I12:I14) -> 13259.243 | J15: =SUM(J12:J14) -> 13561.483 | K15: =SUM(K12:K14) -> 13904.993
B16: Interest Income (Expense) | D16: =-Sheet2!B19 -> -1361 | E16: =-Sheet2!C19 -> -1506 | F16: =-Sheet2!D19 -> -1582 | G16: =G32*G15 -> -1564.6738 | H16: =H32*H15 -> -1635.7189 | I16: =I32*I15 -> -1674.6557 | J16: =J32*J15 -> -1706.6719 | K16: =K32*K15 -> -1756.7581
B17: Other Income (Expense) | D17: =-Sheet2!B20 -> 236 | E17: =-Sheet2!C20 -> 139 | F17: =-Sheet2!D20 -> 87 | G17: - | H17: - | I17: - | J17: - | K17: -
B18: Pretax Income | D18: =SUM(D15:D17) -> 10522 | E18: =SUM(E15:E17) -> 10345 | F18: =SUM(F15:F17) -> 10897 | G18: =SUM(G15:G17) -> 11016.353 | H18: =SUM(H15:H17) -> 11256.924 | I18: =SUM(I15:I17) -> 11584.587 | J18: =SUM(J15:J17) -> 11854.811 | K18: =SUM(K15:K17) -> 12148.235
B19: Tax Provision1 (Income) | D19: =-Sheet2!B22 -> -2053 | E19: =-Sheet2!C22 -> -2121 | F19: =-Sheet2!D22 -> -2334 | G19: =-G33*G18 -> -2313.4342 | H19: =-H33*H18 -> -2363.9541 | I19: =-I33*I18 -> -2432.7634 | J19: =-J33*J18 -> -2489.5102 | K19: =-K33*K18 -> -2551.1293
B20: Net Income | D20: =SUM(D18:D19) -> 8469 | E20: =SUM(E18:E19) -> 8224 | F20: =SUM(F18:F19) -> 8563 | G20: =SUM(G18:G19) -> 8702.9192 | H20: =SUM(H18:H19) -> 8892.9702 | I20: =SUM(I18:I19) -> 9151.8241 | J20: =SUM(J18:J19) -> 9365.3005 | K20: =SUM(K18:K19) -> 9597.1055
B22: EBIT | D22: =D15 -> 11647 | E22: =E15 -> 11712 | F22: =F15 -> 12392 | G22: =G15 -> 12581.027 | H22: =H15 -> 12892.643 | I22: =I15 -> 13259.243 | J22: =J15 -> 13561.483 | K22: =K15 -> 13904.993
B23: Depreciation & Amortization1 | D23: ='Cash flows'!D8 -> 1978 | E23: ='Cash flows'!E8 -> 2097 | F23: ='Cash flows'!F8 -> 2199 | G23: ='Cash flows'!G8 -> 2207.1648 | H23: ='Cash flows'!H8 -> 2290.59 | I23: ='Cash flows'!I8 -> 2376.8069 | J23: ='Cash flows'!J8 -> 2465.9031 | K23: ='Cash flows'!K8 -> 2557.9686
B24: EBITDA | D24: =D22+D23 -> 13625 | E24: =E22+E23 -> 13809 | F24: =F22+F23 -> 14591 | G24: =G22+G23 -> 14788.192 | H24: =H22+H23 -> 15183.233 | I24: =I22+I23 -> 15636.05 | J24: =J22+J23 -> 16027.386 | K24: =K22+K23 -> 16462.961
B26: Income Statement Assumptions | C26: Units | D26: 45291 | E26: =EOMONTH(D26,12) -> 45657 | F26: =EOMONTH(E26,12) -> 46022 | G26: =EOMONTH(F26,12) -> 46387 | H26: =EOMONTH(G26,12) -> 46752 | I26: =EOMONTH(H26,12) -> 47118 | J26: =EOMONTH(I26,12) -> 47483 | K26: =EOMONTH(J26,12) -> 47848
B27: Revenue Growth | C27: % | D27: 0.1 | E27: =(E10-D10)/D10 -> 0.016709814 | F27: =(F10-E10)/E10 -> 0.037229938 | G27: 0.025 | H27: 0.025 | I27: 0.025 | J27: 0.025 | K27: 0.025
B28: Cost of Sales % Revenues | D28: =D11/D10 -> -0.42876755 | E28: =E11/E10 -> -0.43248457 | F28: =F11/F10 -> -0.42592524 | G28: =AVERAGE(D28:F28) -> -0.42905912 | H28: =AVERAGE(E28:G28) -> -0.42915631 | I28: =AVERAGE(F28:H28) -> -0.42804689 | J28: =AVERAGE(G28:I28) -> -0.42875411 | K28: =AVERAGE(H28:J28) -> -0.42865243
B29: Operating Expenses(% of Revenue) | D29: =D13/D10 -> -0.099395936 | E29: =E13/E10 -> -0.09841821 | F29: =F13/F10 -> -0.09615027 | G29: =AVERAGE(D29:F29) -> -0.097988139 | H29: =AVERAGE(E29:G29) -> -0.097518873 | I29: =AVERAGE(F29:H29) -> -0.097219094 | J29: =AVERAGE(G29:I29) -> -0.097575368 | K29: =AVERAGE(H29:J29) -> -0.097437778
B30: D&A as a % of Revenue | D30: =D23/D10 -> 0.077586883 | E30: =E23/E10 -> 0.080902778 | F30: =F23/F10 -> 0.081792821 | G30: =AVERAGE(D30:F30) -> 0.080094161 | H30: =G30+0.1% -> 0.081094161 | I30: =H30+0.1% -> 0.082094161 | J30: =I30+0.1% -> 0.083094161 | K30: =J30+0.1% -> 0.084094161
B31: Other Expenses as a % of Revenue | D31: =D14/D10 -> -0.014983918 | E31: =E14/E10 -> -0.01724537 | F31: =F14/F10 -> -0.016998326 | G31: =AVERAGE(D31:F31) -> -0.016409205 | H31: =AVERAGE(E31:G31) -> -0.0168843 | I31: =AVERAGE(F31:H31) -> -0.016763944 | J31: =AVERAGE(G31:I31) -> -0.016685816 | K31: =AVERAGE(H31:J31) -> -0.01677802
B32: Interest Income(% of income) | D32: =D16/D15 -> -0.11685413 | E32: =E16/E15 -> -0.12858607 | F32: =F16/F15 -> -0.12766301 | G32: =AVERAGE(D32:F32) -> -0.12436773 | H32: =AVERAGE(E32:G32) -> -0.12687227 | I32: =AVERAGE(F32:H32) -> -0.126301 | J32: =AVERAGE(G32:I32) -> -0.125847 | K32: =AVERAGE(H32:J32) -> -0.12634009
B33: Taxes % of Profit Before Tax | D33: =D19/D18 -> -0.195115 | E33: =E19/E18 -> -0.20502658 | F33: =F19/F18 -> -0.21418739 | G33: 0.21 | H33: 0.21 | I33: 0.21 | J33: 0.21 | K33: 0.21
B35: Source:ValueInvesting.io

Sheet Balance sheet
B3: Statement of Financial position | G3: Projections
B4: Amounts in millions | D4: Units | E4: 45657 | F4: =EOMONTH(E4,12) -> 46022 | G4: =EOMONTH(F4,12) -> 46387 | H4: =EOMONTH(G4,12) -> 46752 | I4: =EOMONTH(H4,12) -> 47118 | J4: =EOMONTH(I4,12) -> 47483 | K4: =EOMONTH(J4,12) -> 47848
D5: $m | E5: $ | F5: $ | G5: $ | H5: $ | I5: $ | J5: $ | K5: $
B6: Assets
B7: Cash and equivalents | E7: ='Cash flows'!E27 -> 1086 | F7: ='Cash flows'!F27 -> 775 | G7: =AVERAGE(E7:F7) -> 930.5 | H7: =AVERAGE(F7:G7) -> 852.75 | I7: =AVERAGE(G7:H7) -> 891.625 | J7: =AVERAGE(H7:I7) -> 872.1875 | K7: =AVERAGE(I7:J7) -> 881.90625
B8: Accounts and notes receivable | E8: 2383 | F8: 2466 | G8: =AVERAGE(E8:F8) -> 2424.5 | H8: =AVERAGE(F8:G8) -> 2445.25 | I8: =AVERAGE(G8:H8) -> 2434.875 | J8: =AVERAGE(H8:I8) -> 2440.0625 | K8: =AVERAGE(I8:J8) -> 2437.4688
B9: Inventories & other | E9: =SUM(Sheet2!C76,Sheet2!C77) -> 1130 | F9: =SUM(Sheet2!D76,Sheet2!D77) -> 924 | G9: =AVERAGE(E9:F9) -> 1027 | H9: =AVERAGE(F9:G9) -> 975.5 | I9: =AVERAGE(G9:H9) -> 1001.25 | J9: =AVERAGE(H9:I9) -> 988.375 | K9: =AVERAGE(I9:J9) -> 994.8125
B10: Net PPE, Goodwill & Intangibles | E10: =Sheet2!C88 -> 25295 | F10: =Sheet2!D88 -> 28241 | G10: =AVERAGE(E10:F10) -> 26768 | H10: =AVERAGE(F10:G10) -> 27504.5 | I10: =AVERAGE(G10:H10) -> 27136.25 | J10: =AVERAGE(H10:I10) -> 27320.375 | K10: =AVERAGE(I10:J10) -> 27228.312
B11: Op, lease assets | E11: =SUM(Sheet2!C84) -> 13339 | F11: =SUM(Sheet2!D84) -> 14606 | G11: =AVERAGE(E11:F11) -> 13972.5 | H11: =AVERAGE(F11:G11) -> 14289.25 | I11: =AVERAGE(G11:H11) -> 14130.875 | J11: =AVERAGE(H11:I11) -> 14210.062 | K11: =AVERAGE(I11:J11) -> 14170.469
B12: Other assets | E12: =SUM(Sheet2!C83) -> 11950 | F12: =SUM(Sheet2!D83) -> 12505 | G12: =AVERAGE(E12:F12) -> 12227.5 | H12: =AVERAGE(F12:G12) -> 12366.25 | I12: =AVERAGE(G12:H12) -> 12296.875 | J12: =AVERAGE(H12:I12) -> 12331.562 | K12: =AVERAGE(I12:J12) -> 12314.219
B13: Total assets | E13: =SUM(E7:E12) -> 55183 | F13: =SUM(F7:F12) -> 59517 | G13: =SUM(G7:G12) -> 57350 | H13: =SUM(H7:H12) -> 58433.5 | I13: =SUM(I7:I12) -> 57891.75 | J13: =SUM(J7:J12) -> 58162.625 | K13: =SUM(K7:K12) -> 58027.188
B14: Liabilities & Equity
B15: Accounts payable | E15: =Sheet2!C91 -> 1029 | F15: =Sheet2!D91 -> 1149 | G15: =AVERAGE(E15:F15) -> 1089 | H15: =AVERAGE(F15:G15) -> 1119 | I15: =AVERAGE(G15:H15) -> 1104 | J15: =AVERAGE(H15:I15) -> 1111.5 | K15: =AVERAGE(I15:J15) -> 1107.75
B16: Accrued liabilities | E16: =SUM(Sheet2!C93:C96) -> 2196 | F16: =SUM(Sheet2!D93:D96) -> 2518 | G16: =AVERAGE(E16:F16) -> 2357 | H16: =AVERAGE(F16:G16) -> 2437.5 | I16: =AVERAGE(G16:H16) -> 2397.25 | J16: =AVERAGE(H16:I16) -> 2417.375 | K16: =AVERAGE(I16:J16) -> 2407.3125
B17: Current lease liability | E17: =Sheet2!C92 -> 636 | F17: =Sheet2!D92 -> 694 | G17: =AVERAGE(E17:F17) -> 665 | H17: =AVERAGE(F17:G17) -> 679.5 | I17: =AVERAGE(G17:H17) -> 672.25 | J17: =AVERAGE(H17:I17) -> 675.875 | K17: =AVERAGE(I17:J17) -> 674.0625
B18: Total Debt | E18: =SUM(Sheet2!C98,) -> 38424 | F18: =SUM(Sheet2!D98,) -> 39973 | G18: =AVERAGE(E18:F18) -> 39198.5 | H18: =AVERAGE(F18:G18) -> 39585.75 | I18: =AVERAGE(G18:H18) -> 39392.125 | J18: =AVERAGE(H18:I18) -> 39488.938 | K18: =AVERAGE(I18:J18) -> 39440.531
B19: Op lease liabilities | E19: =SUM(Sheet2!C99:C101,Sheet2!C103) -> 15924 | F19: =SUM(Sheet2!D99:D101,Sheet2!D103) -> 16269 | G19: =AVERAGE(E19:F19) -> 16096.5 | H19: =AVERAGE(F19:G19) -> 16182.75 | I19: =AVERAGE(G19:H19) -> 16139.625 | J19: =AVERAGE(H19:I19) -> 16161.188 | K19: =AVERAGE(I19:J19) -> 16150.406
B20: Other liabilities | E20: =Sheet2!C102 -> 771 | F20: =Sheet2!D102 -> 704 | G20: =AVERAGE(E20:F20) -> 737.5 | H20: =AVERAGE(F20:G20) -> 720.75 | I20: =AVERAGE(G20:H20) -> 729.125 | J20: =AVERAGE(H20:I20) -> 724.9375 | K20: =AVERAGE(I20:J20) -> 727.03125
B21: Total Liabilities | E21: =SUM(E15:E20) -> 58980 | F21: =SUM(F15:F20) -> 61307 | G21: =SUM(G15:G20) -> 60143.5 | H21: =SUM(H15:H20) -> 60725.25 | I21: =SUM(I15:I20) -> 60434.375 | J21: =SUM(J15:J20) -> 60579.812 | K21: =SUM(K15:K20) -> 60507.094
B23: Common shareholders equity | E23: =Sheet2!C111 -> -3797 | F23: =Sheet2!D111 -> -1791 | G23: =AVERAGE(E23:F23) -> -2794 | H23: =AVERAGE(F23:G23) -> -2292.5 | I23: =AVERAGE(G23:H23) -> -2543.25 | J23: =AVERAGE(H23:I23) -> -2417.875 | K23: =AVERAGE(I23:J23) -> -2480.5625
B24: Total liabilities and shareholders' equity (deficit) | E24: =SUM(E21:E23) -> 55183 | F24: =SUM(F21:F23) -> 59516 | G24: =SUM(G21:G23) -> 57349.5 | H24: =SUM(H21:H23) -> 58432.75 | I24: =SUM(I21:I23) -> 57891.125 | J24: =SUM(J21:J23) -> 58161.938 | K24: =SUM(K21:K23) -> 58026.531

Sheet Cash flows
B3: Statement of Cash flows | G3: Projections
B4: Amounts in millions | C4: Units | D4: 45291 | E4: =EOMONTH(D4,12) -> 45657 | F4: =EOMONTH(E4,12) -> 46022 | G4: =EOMONTH(F4,12) -> 46387 | H4: =EOMONTH(G4,12) -> 46752 | I4: =EOMONTH(H4,12) -> 47118 | J4: =EOMONTH(I4,12) -> 47483 | K4: =EOMONTH(J4,12) -> 47848
C5: $m
B6: Operating Cash flow
B7: Net Income | D7: ='Income Statement'!D20 -> 8469 | E7: ='Income Statement'!E20 -> 8224 | F7: ='Income Statement'!F20 -> 8563 | G7: ='Income Statement'!G20 -> 8702.9192 | H7: ='Income Statement'!H20 -> 8892.9702 | I7: ='Income Statement'!I20 -> 9151.8241 | J7: ='Income Statement'!J20 -> 9365.3005 | K7: ='Income Statement'!K20 -> 9597.1055
B8: Depreciation & Amortization | D8: =Sheet2!B35 -> 1978 | E8: =Sheet2!C35 -> 2097 | F8: =Sheet2!D35 -> 2199 | G8: ='Income Statement'!G30*'Income Statement'!G10 -> 2207.1648 | H8: ='Income Statement'!H30*'Income Statement'!H10 -> 2290.59 | I8: ='Income Statement'!I30*'Income Statement'!I10 -> 2376.8069 | J8: ='Income Statement'!J30*'Income Statement'!J10 -> 2465.9031 | K8: ='Income Statement'!K30*'Income Statement'!K10 -> 2557.9686
B9: Other Items | D9: =SUM(Sheet2!B36:B39) -> -727 | E9: =SUM(Sheet2!C36:C39) -> -436 | F9: =SUM(Sheet2!D36:D39) -> -317 | G9: =AVERAGE(D9:F9) -> -493.33333 | H9: -105.66667 | I9: -105.66667 | J9: -105.66667 | K9: -105.66667
B10: Changes in working capital items: | D10: =SUM(Sheet2!B41:B45) -> -108 | E10: =SUM(Sheet2!C41:C45) -> -438 | F10: =SUM(Sheet2!D41:D45) -> 106 | G10: =AVERAGE(D10:F10) -> -146.66667 | H10: =AVERAGE(E10:G10) -> -159.55556 | I10: =AVERAGE(F10:H10) -> -66.740741 | J10: =AVERAGE(G10:I10) -> -124.32099 | K10: =AVERAGE(H10:J10) -> -116.87243
B11: Cash provided by operations | D11: =SUM(D7:D10) -> 9612 | E11: =SUM(E7:E10) -> 9447 | F11: =SUM(F7:F10) -> 10551 | G11: =SUM(G7:G10) -> 10270.084 | H11: =SUM(H7:H10) -> 10918.338 | I11: =SUM(I7:I10) -> 11356.224 | J11: =SUM(J7:J10) -> 11601.216 | K11: =SUM(K7:K10) -> 11932.535
B12: Investing Cash Flow
B13: Capital expenditures | D13: -2357 | E13: -2775 | F13: -3365 | G13: -3700 | H13: =G13-300 -> -4000 | I13: =H13-300 -> -4300 | J13: =I13-300 -> -4600 | K13: =J13-300 -> -4900
B14: Acquisitions and other | D14: =SUM(Sheet2!B49:B53) -> -827 | E14: =SUM(Sheet2!C49:C53) -> -2571 | F14: =SUM(Sheet2!D49:D53) -> -457 | G14: =AVERAGE(D14:F14) -> -1285 | H14: =AVERAGE(E14:G14) -> -1437.6667 | I14: =AVERAGE(F14:H14) -> -1059.8889 | J14: =AVERAGE(G14:I14) -> -1260.8519 | K14: =AVERAGE(H14:J14) -> -1252.8025
B15: Cash used for investing activities | D15: =SUM(D13:D14) -> -3184 | E15: =SUM(E13:E14) -> -5346 | F15: =SUM(F13:F14) -> -3822 | G15: =SUM(G13:G14) -> -4985 | H15: =SUM(H13:H14) -> -5437.6667 | I15: =SUM(I13:I14) -> -5359.8889 | J15: =SUM(J13:J14) -> -5860.8519 | K15: =SUM(K13:K14) -> -6152.8025
B16: Financing activities
B17: Net short-term borrowings | D17: 213 | E17: 326 | F17: 6 | G17: 50 | H17: 50 | I17: 50 | J17: 50 | K17: 50
B18: Long-term financing issuances and repayments | D18: =SUM(Sheet2!B57:B58) -> 2780 | E18: =SUM(Sheet2!C57:C58) -> -397 | F18: =SUM(Sheet2!D57:D58) -> -78 | G18: =AVERAGE(D18:F18) -> 768.33333 | H18: =AVERAGE(E18:G18) -> 97.777778 | I18: =AVERAGE(F18:H18) -> 262.7037 | J18: =AVERAGE(G18:I18) -> 376.2716 | K18: =AVERAGE(H18:J18) -> 245.58436
B19: Treasury stock purchases | D19: -3054 | E19: -2824 | F19: -2056 | G19: =AVERAGE(D19:F19) -> -2644.6667 | H19: =AVERAGE(E19:G19) -> -2508.2222 | I19: =AVERAGE(F19:H19) -> -2402.963 | J19: =AVERAGE(G19:I19) -> -2518.6173 | K19: =AVERAGE(H19:J19) -> -2476.6008
B20: Common stock dividends | D20: -4533 | E20: -4870 | F20: -5115 | G20: =AVERAGE(D20:F20) -> -4839.3333 | H20: =AVERAGE(E20:G20) -> -4941.4444 | I20: =AVERAGE(F20:H20) -> -4965.2593 | J20: =AVERAGE(G20:I20) -> -4915.3457 | K20: =AVERAGE(H20:J20) -> -4940.6831
B21: Proceeds and other | D21: =SUM(Sheet2!B61:B62) -> 220 | E21: =SUM(Sheet2!C61:C62) -> 272 | F21: =SUM(Sheet2!D61:D62) -> 118 | G21: =AVERAGE(D21:F21) -> 203.33333 | H21: =AVERAGE(E21:G21) -> 197.77778 | I21: =AVERAGE(F21:H21) -> 173.03704 | J21: =AVERAGE(G21:I21) -> 191.38272 | K21: =AVERAGE(H21:J21) -> 187.39918
B22: Cash used for financing activities | D22: =SUM(D17:D21) -> -4374 | E22: =SUM(E17:E21) -> -7493 | F22: =SUM(F17:F21) -> -7125 | G22: =SUM(G17:G21) -> -6462.3333 | H22: =SUM(H17:H21) -> -7104.1111 | I22: =SUM(I17:I21) -> -6882.4815 | J22: =SUM(J17:J21) -> -6816.3086 | K22: =SUM(K17:K21) -> -6934.3004
B24: Effect of exchange rates on cash and equivalents | D24: =Sheet2!B64 -> -58 | E24: =Sheet2!C64 -> -101 | F24: =Sheet2!D64 -> 86 | G24: =AVERAGE(D24:F24) -> -24.333333 | H24: =AVERAGE(E24:G24) -> -13.111111 | I24: =AVERAGE(F24:H24) -> 16.185185 | J24: =AVERAGE(G24:I24) -> -7.0864198 | K24: =AVERAGE(H24:J24) -> -1.3374486
B25: Cash and equivalents increase (decrease) | D25: =SUM(D11,D15,D22,D24) -> 1996 | E25: =SUM(E11,E15,E22,E24) -> -3493 | F25: =SUM(F11,F15,F22,F24) -> -310 | G25: =AVERAGE(D25:F25) -> -602.33333 | H25: =AVERAGE(E25:G25) -> -1468.4444 | I25: =AVERAGE(F25:H25) -> -793.59259 | J25: =AVERAGE(G25:I25) -> -954.79012 | K25: =AVERAGE(H25:J25) -> -1072.2757
B26: Cash and equivalents at beginning of year | D26: =Sheet2!B66 -> 2584 | E26: =Sheet2!C66 -> 4579 | F26: =Sheet2!D66 -> 1085 | G26: =AVERAGE(D26:F26) -> 2749.3333 | H26: =AVERAGE(E26:G26) -> 2804.4444 | I26: =AVERAGE(F26:H26) -> 2212.9259 | J26: =AVERAGE(G26:I26) -> 2588.9012 | K26: =AVERAGE(H26:J26) -> 2535.4239
B27: Cash and equivalents at end of year | D27: =SUM(D25,D26) -> 4580 | E27: =SUM(E25,E26) -> 1086 | F27: =SUM(F25,F26) -> 775 | G27: =AVERAGE(D27:F27) -> 2147 | H27: =AVERAGE(E27:G27) -> 1336 | I27: =AVERAGE(F27:H27) -> 1419.3333 | J27: =AVERAGE(G27:I27) -> 1634.1111 | K27: =AVERAGE(H27:J27) -> 1463.1481
B28: Supplemental cash flow disclosures
B29: Interest Paid | D29: 1287 | E29: 1523 | F29: 1555 | G29: =AVERAGE(D29:F29) -> 1455 | H29: =AVERAGE(E29:G29) -> 1511 | I29: =AVERAGE(F29:H29) -> 1507 | J29: =AVERAGE(G29:I29) -> 1491 | K29: =AVERAGE(H29:J29) -> 1503

Sheet DCF
B3: McDonalds Corp
B4: MCD
B5: Discounted Cash flow Analysis
G6: 1 | H6: 2 | I6: 3 | J6: 4 | K6: 5
B7: DCF Analysis | G7: Projections
B8: Amounts in millions | C8: Units | D8: =E8-1 -> 2023 | E8: =F8-1 -> 2024 | F8: 2025 | G8: =F8+1 -> 2026 | H8: =G8+1 -> 2027 | I8: =H8+1 -> 2028 | J8: =I8+1 -> 2029 | K8: =J8+1 -> 2030
B9: Revenue | C9: $m | D9: ='Income Statement'!D10 -> 25494 | E9: ='Income Statement'!E10 -> 25920 | F9: ='Income Statement'!F10 -> 26885 | G9: ='Income Statement'!G10 -> 27557.125 | H9: ='Income Statement'!H10 -> 28246.053 | I9: ='Income Statement'!I10 -> 28952.204 | J9: ='Income Statement'!J10 -> 29676.01 | K9: ='Income Statement'!K10 -> 30417.91
B10: % of Revenue growth | D10: ='Income Statement'!D27 -> 0.1 | E10: ='Income Statement'!E27 -> 0.016709814 | F10: ='Income Statement'!F27 -> 0.037229938 | G10: ='Income Statement'!G27 -> 0.025 | H10: ='Income Statement'!H27 -> 0.025 | I10: ='Income Statement'!I27 -> 0.025 | J10: ='Income Statement'!J27 -> 0.025 | K10: ='Income Statement'!K27 -> 0.025
B12: EBIT | D12: ='Income Statement'!D22 -> 11647 | E12: ='Income Statement'!E22 -> 11712 | F12: ='Income Statement'!F22 -> 12392 | G12: ='Income Statement'!G22 -> 12581.027 | H12: ='Income Statement'!H22 -> 12892.643 | I12: ='Income Statement'!I22 -> 13259.243 | J12: ='Income Statement'!J22 -> 13561.483 | K12: ='Income Statement'!K22 -> 13904.993
B13: EBIT margin | D13: =D12/D9 -> 0.45685259 | E13: =E12/E9 -> 0.45185185 | F13: =F12/F9 -> 0.46092617 | G13: =G12/G9 -> 0.45654354 | H13: =H12/H9 -> 0.45644052 | I13: =I12/I9 -> 0.45797007 | J13: =J12/J9 -> 0.45698471 | K13: =K12/K9 -> 0.45713177
B15: Taxes | D15: ='Income Statement'!D19 -> -2053 | E15: ='Income Statement'!E19 -> -2121 | F15: ='Income Statement'!F19 -> -2334 | G15: ='Income Statement'!G19 -> -2313.4342 | H15: ='Income Statement'!H19 -> -2363.9541 | I15: ='Income Statement'!I19 -> -2432.7634 | J15: ='Income Statement'!J19 -> -2489.5102 | K15: ='Income Statement'!K19 -> -2551.1293
B16: % of EBIT | D16: =D15/D12 -> -0.17626857 | E16: =E15/E12 -> -0.18109631 | F16: =F15/F12 -> -0.18834732 | G16: =G15/G12 -> -0.18388278 | H16: =H15/H12 -> -0.18335682 | I16: =I15/I12 -> -0.18347679 | J16: =J15/J12 -> -0.18357213 | K16: =K15/K12 -> -0.18346858
B18: EBIAT | D18: =D12-D15 -> 13700 | E18: =E12-E15 -> 13833 | F18: =F12-F15 -> 14726 | G18: =G12-G15 -> 14894.462 | H18: =H12-H15 -> 15256.597 | I18: =I12-I15 -> 15692.007 | J18: =J12-J15 -> 16050.993 | K18: =K12-K15 -> 16456.122
B20: Depreciation & Amortization | D20: ='Cash flows'!D8 -> 1978 | E20: ='Cash flows'!E8 -> 2097 | F20: ='Cash flows'!F8 -> 2199 | G20: ='Cash flows'!G8 -> 2207.1648 | H20: ='Cash flows'!H8 -> 2290.59 | I20: ='Cash flows'!I8 -> 2376.8069 | J20: ='Cash flows'!J8 -> 2465.9031 | K20: ='Cash flows'!K8 -> 2557.9686
B21: % of Revenue | D21: =D20/D9 -> 0.077586883 | E21: =E20/E9 -> 0.080902778 | F21: =F20/F9 -> 0.081792821 | G21: =G20/G9 -> 0.080094161 | H21: =H20/H9 -> 0.081094161 | I21: =I20/I9 -> 0.082094161 | J21: =J20/J9 -> 0.083094161 | K21: =K20/K9 -> 0.084094161
B23: Capital Expenditure | D23: ='Cash flows'!D13 -> -2357 | E23: ='Cash flows'!E13 -> -2775 | F23: ='Cash flows'!F13 -> -3365 | G23: ='Cash flows'!G13 -> -3700 | H23: ='Cash flows'!H13 -> -4000 | I23: ='Cash flows'!I13 -> -4300 | J23: ='Cash flows'!J13 -> -4600 | K23: ='Cash flows'!K13 -> -4900
B24: % of Revenue | G24: =G23/G9 -> -0.13426655 | H24: =H23/H9 -> -0.14161271 | I24: =I23/I9 -> -0.14852064 | J24: =J23/J9 -> -0.15500736 | K24: =K23/K9 -> -0.16108931
D25: 2023 | E25: 2024 | F25: 2025 | G25: 2026 | H25: 2027 | I25: 2028 | J25: 2029 | K25: 2030
B26: Net Working Capital | D26: 1438 | E26: 1410 | F26: 1378 | G26: =AVERAGE(D26:F26) -> 1408.6667 | H26: =AVERAGE(E26:G26) -> 1398.8889 | I26: =AVERAGE(F26:H26) -> 1395.1852 | J26: =AVERAGE(G26:I26) -> 1400.9136 | K26: =AVERAGE(H26:J26) -> 1398.3292
B28: Changes in Net Working Capital | D28: 0 | E28: =E26-D26 -> -28 | F28: =F26-E26 -> -32 | G28: =G26-F26 -> 30.666667 | H28: =H26-G26 -> -9.7777778 | I28: =I26-H26 -> -3.7037037 | J28: =J26-I26 -> 5.7283951 | K28: =K26-J26 -> -2.5843621
B30: Unlevered Free Cash Flow | G30: =G18+G20+G23+G28 -> 13432.293 | H30: =H18+H20++H23+H28 -> 13537.409 | I30: =I18+I20++I23+I28 -> 13765.11 | J30: =J18+J20++J23+J28 -> 13922.624 | K30: =K18+K20++K23+K28 -> 14111.506
B31: Discounting Factor | G31: =1/((1+$E$51)^G6) -> 0.94129581 | H31: =1/((1+$E$51)^H6) -> 0.8860378 | I31: =1/((1+$E$51)^I6) -> 0.83402367 | J31: =1/((1+$E$51)^J6) -> 0.78506299 | K31: =1/((1+$E$51)^K6) -> 0.7389765
B32: Present value of Free Cash Flow | G32: =G30*G31 -> 12643.761 | H32: =H30*H31 -> 11994.657 | I32: =I30*I31 -> 11480.427 | J32: =J30*J31 -> 10930.137 | K32: =K30*K31 -> 10428.072
B34: WACC | F34: Terminal Value
B35: Weighted Average Cost of Capital | F35: Terminal Value - Perpetuity Growth
F36: ="FY"&TEXT(K8,"0")&"E Unlevered Free Cash Flow" -> FY2030E Unlevered Free Cash Flow | I36: =K30 -> 14111.506
B37: Risk free rate (Rf) | E37: 0.0502 | F37: Perpetuity growth rate | I37: 0.03
B38: Equity Beta | E38: 0.41 | F38: Terminal Value | I38: =(I36 * (1 + I37)) / (E51 - I37) -> 449087.59
B39: Equity risk premium (Rm - Rf) | E39: 0.0445 | F39: PV of Terminal value | I39: =I38*K31 -> 331865.18
B40: Cost of Equity (Ke) | E40: =E37+E38*E39 -> 0.068445
B42: Cost of debt | E42: 0.044 | F42: Implied value per share
B43: Tax rate | E43: 0.21 | F43: DCF Value - Perpetuity Growth
B44: After-tax Cost of Debt (Kdt) | E44: =E42*(1-E43) -> 0.03476 | F44: ="NPV of UFCF "&TEXT(G8,"0")&" - "&TEXT(K8,"0") -> NPV of UFCF 2026 - 2030 | I44: =SUM(G32:K32) -> 57477.054
F45: PV of Terminal Value | I45: =I39 -> 331865.18
B46: Percentage of Capital | C46: Price ($) | F46: Implied Enterprise Value | I46: =SUM(I44:I45) -> 389342.23
B47: Debt | D47: ='Balance sheet'!F18 -> 39973 | E47: =D47/D49 -> 0.18048706 | F47: Less: Debt | I47: =-'Balance sheet'!F18 -> -39973
B48: Equity | C48: 253.35 | D48: =C48*$I$50 -> 181499.94 | E48: =D48/D49 -> 0.81951294 | F48: Add: Cash | I48: ='Balance sheet'!F7 -> 775
B49: Total capital | D49: =SUM(D47:D48) -> 221472.94 | E49: 1 | F49: Implied Equity Value | I49: =SUM(I46:I48) -> 350144.23
F50: Diluted shares | I50: =716.4 -> 716.4
B51: Weighted Average Cost of Capital | E51: =E47*E44+E48*E40 -> 0.062365293 | F51: Implied Value Per Share | I51: =I49/I50 -> 488.75521
